[2024-07-04T19:30:34.314+0000] {local_task_job_runner.py:120} INFO - ::group::Pre task execution logs
[2024-07-04T19:30:34.364+0000] {taskinstance.py:2076} INFO - Dependencies all met for dep_context=non-requeueable deps ti=<TaskInstance: preprocess_data.preprocess_data_task manual__2024-07-04T19:30:32.814677+00:00 [queued]>
[2024-07-04T19:30:34.377+0000] {taskinstance.py:2076} INFO - Dependencies all met for dep_context=requeueable deps ti=<TaskInstance: preprocess_data.preprocess_data_task manual__2024-07-04T19:30:32.814677+00:00 [queued]>
[2024-07-04T19:30:34.378+0000] {taskinstance.py:2306} INFO - Starting attempt 1 of 1
[2024-07-04T19:30:34.410+0000] {taskinstance.py:2330} INFO - Executing <Task(PythonOperator): preprocess_data_task> on 2024-07-04 19:30:32.814677+00:00
[2024-07-04T19:30:34.419+0000] {standard_task_runner.py:90} INFO - Running: ['airflow', 'tasks', 'run', 'preprocess_data', 'preprocess_data_task', 'manual__2024-07-04T19:30:32.814677+00:00', '--job-id', '38', '--raw', '--subdir', 'DAGS_FOLDER/dags.py', '--cfg-path', '/tmp/tmpbx8g2_hu']
[2024-07-04T19:30:34.423+0000] {logging_mixin.py:188} WARNING - /home/airflow/.local/lib/python3.12/site-packages/airflow/task/task_runner/standard_task_runner.py:61 DeprecationWarning: This process (pid=180) is multi-threaded, use of fork() may lead to deadlocks in the child.
[2024-07-04T19:30:34.423+0000] {standard_task_runner.py:91} INFO - Job 38: Subtask preprocess_data_task
[2024-07-04T19:30:34.424+0000] {standard_task_runner.py:63} INFO - Started process 181 to run task
[2024-07-04T19:30:34.523+0000] {task_command.py:426} INFO - Running <TaskInstance: preprocess_data.preprocess_data_task manual__2024-07-04T19:30:32.814677+00:00 [running]> on host e5d5a2a94ba7
[2024-07-04T19:30:34.717+0000] {taskinstance.py:2648} INFO - Exporting env vars: AIRFLOW_CTX_DAG_OWNER='airflow' AIRFLOW_CTX_DAG_ID='preprocess_data' AIRFLOW_CTX_TASK_ID='preprocess_data_task' AIRFLOW_CTX_EXECUTION_DATE='2024-07-04T19:30:32.814677+00:00' AIRFLOW_CTX_TRY_NUMBER='1' AIRFLOW_CTX_DAG_RUN_ID='manual__2024-07-04T19:30:32.814677+00:00'
[2024-07-04T19:30:34.717+0000] {taskinstance.py:430} INFO - ::endgroup::
[2024-07-04T19:30:34.830+0000] {taskinstance.py:441} INFO - ::group::Post task execution logs
[2024-07-04T19:30:34.830+0000] {taskinstance.py:2905} ERROR - Task failed with exception
Traceback (most recent call last):
  File "/home/airflow/.local/lib/python3.12/site-packages/urllib3/connection.py", line 198, in _new_conn
    sock = connection.create_connection(
           ^^^^^^^^^^^^^^^^^^^^^^^^^^^^^
  File "/home/airflow/.local/lib/python3.12/site-packages/urllib3/util/connection.py", line 60, in create_connection
    for res in socket.getaddrinfo(host, port, family, socket.SOCK_STREAM):
               ^^^^^^^^^^^^^^^^^^^^^^^^^^^^^^^^^^^^^^^^^^^^^^^^^^^^^^^^^^
  File "/usr/local/lib/python3.12/socket.py", line 964, in getaddrinfo
    for res in _socket.getaddrinfo(host, port, family, type, proto, flags):
               ^^^^^^^^^^^^^^^^^^^^^^^^^^^^^^^^^^^^^^^^^^^^^^^^^^^^^^^^^^^
socket.gaierror: [Errno -2] Name or service not known

The above exception was the direct cause of the following exception:

Traceback (most recent call last):
  File "/home/airflow/.local/lib/python3.12/site-packages/urllib3/connectionpool.py", line 793, in urlopen
    response = self._make_request(
               ^^^^^^^^^^^^^^^^^^^
  File "/home/airflow/.local/lib/python3.12/site-packages/urllib3/connectionpool.py", line 496, in _make_request
    conn.request(
  File "/home/airflow/.local/lib/python3.12/site-packages/urllib3/connection.py", line 400, in request
    self.endheaders()
  File "/usr/local/lib/python3.12/http/client.py", line 1331, in endheaders
    self._send_output(message_body, encode_chunked=encode_chunked)
  File "/usr/local/lib/python3.12/http/client.py", line 1091, in _send_output
    self.send(msg)
  File "/usr/local/lib/python3.12/http/client.py", line 1035, in send
    self.connect()
  File "/home/airflow/.local/lib/python3.12/site-packages/urllib3/connection.py", line 238, in connect
    self.sock = self._new_conn()
                ^^^^^^^^^^^^^^^^
  File "/home/airflow/.local/lib/python3.12/site-packages/urllib3/connection.py", line 205, in _new_conn
    raise NameResolutionError(self.host, self, e) from e
urllib3.exceptions.NameResolutionError: <urllib3.connection.HTTPConnection object at 0x7f60b665ab10>: Failed to resolve 'data-warehouse' ([Errno -2] Name or service not known)

The above exception was the direct cause of the following exception:

Traceback (most recent call last):
  File "/home/airflow/.local/lib/python3.12/site-packages/requests/adapters.py", line 486, in send
    resp = conn.urlopen(
           ^^^^^^^^^^^^^
  File "/home/airflow/.local/lib/python3.12/site-packages/urllib3/connectionpool.py", line 847, in urlopen
    retries = retries.increment(
              ^^^^^^^^^^^^^^^^^^
  File "/home/airflow/.local/lib/python3.12/site-packages/urllib3/util/retry.py", line 515, in increment
    raise MaxRetryError(_pool, url, reason) from reason  # type: ignore[arg-type]
    ^^^^^^^^^^^^^^^^^^^^^^^^^^^^^^^^^^^^^^^^^^^^^^^^^^^
urllib3.exceptions.MaxRetryError: HTTPConnectionPool(host='data-warehouse', port=5000): Max retries exceeded with url: /warehouse/process_data (Caused by NameResolutionError("<urllib3.connection.HTTPConnection object at 0x7f60b665ab10>: Failed to resolve 'data-warehouse' ([Errno -2] Name or service not known)"))

During handling of the above exception, another exception occurred:

Traceback (most recent call last):
  File "/home/airflow/.local/lib/python3.12/site-packages/airflow/models/taskinstance.py", line 465, in _execute_task
    result = _execute_callable(context=context, **execute_callable_kwargs)
             ^^^^^^^^^^^^^^^^^^^^^^^^^^^^^^^^^^^^^^^^^^^^^^^^^^^^^^^^^^^^^
  File "/home/airflow/.local/lib/python3.12/site-packages/airflow/models/taskinstance.py", line 432, in _execute_callable
    return execute_callable(context=context, **execute_callable_kwargs)
           ^^^^^^^^^^^^^^^^^^^^^^^^^^^^^^^^^^^^^^^^^^^^^^^^^^^^^^^^^^^^
  File "/home/airflow/.local/lib/python3.12/site-packages/airflow/models/baseoperator.py", line 401, in wrapper
    return func(self, *args, **kwargs)
           ^^^^^^^^^^^^^^^^^^^^^^^^^^^
  File "/home/airflow/.local/lib/python3.12/site-packages/airflow/operators/python.py", line 235, in execute
    return_value = self.execute_callable()
                   ^^^^^^^^^^^^^^^^^^^^^^^
  File "/home/airflow/.local/lib/python3.12/site-packages/airflow/operators/python.py", line 252, in execute_callable
    return self.python_callable(*self.op_args, **self.op_kwargs)
           ^^^^^^^^^^^^^^^^^^^^^^^^^^^^^^^^^^^^^^^^^^^^^^^^^^^^^
  File "/opt/airflow/dags/dags.py", line 44, in preprocess_data
    response = requests.post(url, json=body)
               ^^^^^^^^^^^^^^^^^^^^^^^^^^^^^
  File "/home/airflow/.local/lib/python3.12/site-packages/requests/api.py", line 115, in post
    return request("post", url, data=data, json=json, **kwargs)
           ^^^^^^^^^^^^^^^^^^^^^^^^^^^^^^^^^^^^^^^^^^^^^^^^^^^^
  File "/home/airflow/.local/lib/python3.12/site-packages/requests/api.py", line 59, in request
    return session.request(method=method, url=url, **kwargs)
           ^^^^^^^^^^^^^^^^^^^^^^^^^^^^^^^^^^^^^^^^^^^^^^^^^
  File "/home/airflow/.local/lib/python3.12/site-packages/requests/sessions.py", line 589, in request
    resp = self.send(prep, **send_kwargs)
           ^^^^^^^^^^^^^^^^^^^^^^^^^^^^^^
  File "/home/airflow/.local/lib/python3.12/site-packages/requests/sessions.py", line 703, in send
    r = adapter.send(request, **kwargs)
        ^^^^^^^^^^^^^^^^^^^^^^^^^^^^^^^
  File "/home/airflow/.local/lib/python3.12/site-packages/requests/adapters.py", line 519, in send
    raise ConnectionError(e, request=request)
requests.exceptions.ConnectionError: HTTPConnectionPool(host='data-warehouse', port=5000): Max retries exceeded with url: /warehouse/process_data (Caused by NameResolutionError("<urllib3.connection.HTTPConnection object at 0x7f60b665ab10>: Failed to resolve 'data-warehouse' ([Errno -2] Name or service not known)"))
[2024-07-04T19:30:34.845+0000] {taskinstance.py:1206} INFO - Marking task as FAILED. dag_id=preprocess_data, task_id=preprocess_data_task, run_id=manual__2024-07-04T19:30:32.814677+00:00, execution_date=20240704T193032, start_date=20240704T193034, end_date=20240704T193034
[2024-07-04T19:30:34.875+0000] {standard_task_runner.py:110} ERROR - Failed to execute job 38 for task preprocess_data_task (HTTPConnectionPool(host='data-warehouse', port=5000): Max retries exceeded with url: /warehouse/process_data (Caused by NameResolutionError("<urllib3.connection.HTTPConnection object at 0x7f60b665ab10>: Failed to resolve 'data-warehouse' ([Errno -2] Name or service not known)")); 181)
[2024-07-04T19:30:34.898+0000] {local_task_job_runner.py:240} INFO - Task exited with return code 1
[2024-07-04T19:30:34.919+0000] {taskinstance.py:3503} INFO - 0 downstream tasks scheduled from follow-on schedule check
[2024-07-04T19:30:34.933+0000] {local_task_job_runner.py:222} INFO - ::endgroup::
